Workbook
Name Slicer_burnout_risk: #N/A
Name Slicer_channel_size_tier: #N/A
Name Slicer_Country: #N/A

Sheet Cleaned_Data
A1: rank | B1: Youtuber | C1: subscribers | D1: video views | E1: category | F1: Title | G1: uploads | H1: Country | I1: Abbreviation | J1: channel_type | K1: video_views_rank | L1: country_rank | M1: channel_type_rank | N1: video_views_for_the_last_30_days | O1: lowest_monthly_earnings | P1: highest_monthly_earnings | Q1: lowest_yearly_earnings | R1: highest_yearly_earnings | S1: subscribers_for_last_30_days | T1: created_year | U1: created_month | V1: created_date | W1: Gross tertiary education enrollment (%) | X1: Population | Y1: Unemployment rate | Z1: Urban_population | AA1: Latitude | AB1: Longitude | AC1: upload_frequency | AD1: view_per_upload | AE1: subscribers_per_upload | AF1: subscriber_to_view_ratio | AG1: earnings_per_million_views | AH1: view_per_subscriber | AI1: channel_age(year) | AJ1: monthly_expected_earning | AK1: yearly_expected_earning | AL1: Custom | AM1: engagement_rate | AN1: burnout_risk | AO1: Date | AP1: channel_size_tier | AQ1: estimate_yearly_earnings | AR1: upload_frequency_bucket
A2: 1 | B2: T-Series | C2: 245000000 | D2: 228000000000 | E2: Music | F2: T-Series | G2: 20082 | H2: India | I2: IN | J2: Music | K2: 1 | L2: 1 | M2: 1 | N2: 2258000000 | O2: 564600 | P2: 9000000 | Q2: 6800000 | R2: 108400000 | S2: 2000000 | T2: 2006 | U2: Mar | V2: 13 | W2: 28.1 | X2: 1366417754 | Y2: 5.36 | Z2: 471031528 | AA2: 20.593684 | AB2: 78.96288 | AC2: 92.972222 | AD2: 11353451 | AE2: 12199.98 | AF2: 0.0010745614 | AG2: 39.473684 | AH2: 930.61224 | AI2: 20 | AJ2: 8435400 | AK2: 101600000 | AL2: 100000 | AM2: =youtube_stats_raw[[#This Row],[subscribers_for_last_30_days]] / youtube_stats_raw[[#This Row],[subscribers]] -> 0.0081632653 | AN2: =IF(AND(youtube_stats_raw[[#This Row],[upload_frequency]]>23.1077381,youtube_stats_raw[[#This Row],[ engagement_rate]]<=0),"High",IF(OR(youtube_stats_raw[[#This Row],[upload_frequency]]>23.1077381,youtube_stats_raw[[#This Row],[ engagement_rate]]<=0),"Medium","Low")) -> Medium | AO2: =DATE(T2, MATCH(U2,{"Jan","Feb","Mar","Apr","May","Jun","Jul","Aug","Sep","Oct","Nov","Dec"},0), V2) -> 38789 | AP2: =IF(youtube_stats_raw[[#This Row],[subscribers]]<70000000,"Micro",IF(youtube_stats_raw[[#This Row],[subscribers]]<128000000,"Mid",IF(youtube_stats_raw[[#This Row],[subscribers]]<186000000,"Macro","Mega"))) -> Mega | AQ2: =SUM((youtube_stats_raw[[#This Row],[lowest_yearly_earnings]] + youtube_stats_raw[[#This Row],[highest_yearly_earnings]])/2) -> 57600000 | AR2: =IF(youtube_stats_raw[[#This Row],[upload_frequency]]<=_xlfn.PERCENTILE.INC(AC:AC,0.2),"Very Low",IF(youtube_stats_raw[[#This Row],[upload_frequency]]<=_xlfn.PERCENTILE.INC(AC:AC,0.4),"Low",IF(youtube_stats_raw[[#This Row],[upload_frequency]]<=_xlfn.PERCENTILE.INC(AC:AC,0.6),"Medium",IF(youtube_stats_raw[[#This Row],[upload_frequency]]<=_xlfn.PERCENTILE.INC(AC:AC,0.8),"High","Very High")))) -> Very High
A3: 2 | B3: YouTube Movies | C3: 170000000 | D3: 0 | E3: Film & Animation | F3: youtubemovies | G3: 1 | H3: United States | I3: US | J3: Games | K3: 4055159 | L3: 7670 | M3: 7423 | N3: 12 | O3: 0 | P3: 0 | Q3: 0 | R3: 1 | S3: 0 | T3: 2006 | U3: Mar | V3: 5 | W3: 88.2 | X3: 328239523 | Y3: 14.7 | Z3: 270663028 | AA3: 37.09024 | AB3: -95.712891 | AC3: 0.0046296296 | AD3: 0 | AE3: 170000000 | AF3: 0 | AG3: #NUM! | AH3: 0 | AI3: 20 | AJ3: 0 | AK3: 1 | AL3: 0 | AM3: =youtube_stats_raw[[#This Row],[subscribers_for_last_30_days]] / youtube_stats_raw[[#This Row],[subscribers]] -> 0 | AN3: =IF(AND(youtube_stats_raw[[#This Row],[upload_frequency]]>23.1077381,youtube_stats_raw[[#This Row],[ engagement_rate]]<=0),"High",IF(OR(youtube_stats_raw[[#This Row],[upload_frequency]]>23.1077381,youtube_stats_raw[[#This Row],[ engagement_rate]]<=0),"Medium","Low")) -> Medium | AO3: =DATE(T3, MATCH(U3,{"Jan","Feb","Mar","Apr","May","Jun","Jul","Aug","Sep","Oct","Nov","Dec"},0), V3) -> 38781 | AP3: =IF(youtube_stats_raw[[#This Row],[subscribers]]<70000000,"Micro",IF(youtube_stats_raw[[#This Row],[subscribers]]<128000000,"Mid",IF(youtube_stats_raw[[#This Row],[subscribers]]<186000000,"Macro","Mega"))) -> Macro | AQ3: =SUM((youtube_stats_raw[[#This Row],[lowest_yearly_earnings]] + youtube_stats_raw[[#This Row],[highest_yearly_earnings]])/2) -> 0.5 | AR3: =IF(youtube_stats_raw[[#This Row],[upload_frequency]]<=_xlfn.PERCENTILE.INC(AC:AC,0.2),"Very Low",IF(youtube_stats_raw[[#This Row],[upload_frequency]]<=_xlfn.PERCENTILE.INC(AC:AC,0.4),"Low",IF(youtube_stats_raw[[#This Row],[upload_frequency]]<=_xlfn.PERCENTILE.INC(AC:AC,0.6),"Medium",IF(youtube_stats_raw[[#This Row],[upload_frequency]]<=_xlfn.PERCENTILE.INC(AC:AC,0.8),"High","Very High")))) -> Very Low
A4: 3 | B4: MrBeast | C4: 166000000 | D4: 28368841870 | E4: Entertainment | F4: MrBeast | G4: 741 | H4: United States | I4: US | J4: Entertainment | K4: 48 | L4: 1 | M4: 1 | N4: 1348000000 | O4: 337000 | P4: 5400000 | Q4: 4000000 | R4: 64700000 | S4: 8000000 | T4: 2012 | U4: Feb | V4: 20 | W4: 88.2 | X4: 328239523 | Y4: 14.7 | Z4: 270663028 | AA4: 37.09024 | AB4: -95.712891 | AC4: 5.1458333 | AD4: 38284537 | AE4: 224021.59 | AF4: 0.0058514902 | AG4: 190.34968 | AH4: 170.89664 | AI4: 14 | AJ4: 5063000 | AK4: 60700000 | AL4: 571428.57 | AM4: =youtube_stats_raw[[#This Row],[subscribers_for_last_30_days]] / youtube_stats_raw[[#This Row],[subscribers]] -> 0.048192771 | AN4: =IF(AND(youtube_stats_raw[[#This Row],[upload_frequency]]>23.1077381,youtube_stats_raw[[#This Row],[ engagement_rate]]<=0),"High",IF(OR(youtube_stats_raw[[#This Row],[upload_frequency]]>23.1077381,youtube_stats_raw[[#This Row],[ engagement_rate]]<=0),"Medium","Low")) -> Low | AO4: =DATE(T4, MATCH(U4,{"Jan","Feb","Mar","Apr","May","Jun","Jul","Aug","Sep","Oct","Nov","Dec"},0), V4) -> 40959 | AP4: =IF(youtube_stats_raw[[#This Row],[subscribers]]<70000000,"Micro",IF(youtube_stats_raw[[#This Row],[subscribers]]<128000000,"Mid",IF(youtube_stats_raw[[#This Row],[subscribers]]<186000000,"Macro","Mega"))) -> Macro | AQ4: =SUM((youtube_stats_raw[[#This Row],[lowest_yearly_earnings]] + youtube_stats_raw[[#This Row],[highest_yearly_earnings]])/2) -> 34350000 | AR4: =IF(youtube_stats_raw[[#This Row],[upload_frequency]]<=_xlfn.PERCENTILE.INC(AC:AC,0.2),"Very Low",IF(youtube_stats_raw[[#This Row],[upload_frequency]]<=_xlfn.PERCENTILE.INC(AC:AC,0.4),"Low",IF(youtube_stats_raw[[#This Row],[upload_frequency]]<=_xlfn.PERCENTILE.INC(AC:AC,0.6),"Medium",IF(youtube_stats_raw[[#This Row],[upload_frequency]]<=_xlfn.PERCENTILE.INC(AC:AC,0.8),"High","Very High")))) -> Low
A5: 4 | B5: Cocomelon - Nursery Rhymes | C5: 162000000 | D5: 164000000000 | E5: Education | F5: Cocomelon - Nursery Rhymes | G5: 966 | H5: United States | I5: US | J5: Education | K5: 2 | L5: 2 | M5: 1 | N5: 1975000000 | O5: 493800 | P5: 7900000 | Q5: 5900000 | R5: 94800000 | S5: 1000000 | T5: 2006 | U5: Sep | V5: 1 | W5: 88.2 | X5: 328239523 | Y5: 14.7 | Z5: 270663028 | AA5: 37.09024 | AB5: -95.712891 | AC5: 4.4722222 | AD5: 1.6977226e+08 | AE5: 167701.86 | AF5: 0.00098780488 | AG5: 48.170732 | AH5: 1012.3457 | AI5: 20 | AJ5: 7406200 | AK5: 88900000 | AL5: 50000 | AM5: =youtube_stats_raw[[#This Row],[subscribers_for_last_30_days]] / youtube_stats_raw[[#This Row],[subscribers]] -> 0.0061728395 | AN5: =IF(AND(youtube_stats_raw[[#This Row],[upload_frequency]]>23.1077381,youtube_stats_raw[[#This Row],[ engagement_rate]]<=0),"High",IF(OR(youtube_stats_raw[[#This Row],[upload_frequency]]>23.1077381,youtube_stats_raw[[#This Row],[ engagement_rate]]<=0),"Medium","Low")) -> Low | AO5: =DATE(T5, MATCH(U5,{"Jan","Feb","Mar","Apr","May","Jun","Jul","Aug","Sep","Oct","Nov","Dec"},0), V5) -> 38961 | AP5: =IF(youtube_stats_raw[[#This Row],[subscribers]]<70000000,"Micro",IF(youtube_stats_raw[[#This Row],[subscribers]]<128000000,"Mid",IF(youtube_stats_raw[[#This Row],[subscribers]]<186000000,"Macro","Mega"))) -> Macro | AQ5: =SUM((youtube_stats_raw[[#This Row],[lowest_yearly_earnings]] + youtube_stats_raw[[#This Row],[highest_yearly_earnings]])/2) -> 50350000 | AR5: =IF(youtube_stats_raw[[#This Row],[upload_frequency]]<=_xlfn.PERCENTILE.INC(AC:AC,0.2),"Very Low",IF(youtube_stats_raw[[#This Row],[upload_frequency]]<=_xlfn.PERCENTILE.INC(AC:AC,0.4),"Low",IF(youtube_stats_raw[[#This Row],[upload_frequency]]<=_xlfn.PERCENTILE.INC(AC:AC,0.6),"Medium",IF(youtube_stats_raw[[#This Row],[upload_frequency]]<=_xlfn.PERCENTILE.INC(AC:AC,0.8),"High","Very High")))) -> Low
A6: 5 | B6: SET India | C6: 159000000 | D6: 148000000000 | E6: Shows | F6: SET India | G6: 116536 | H6: India | I6: IN | J6: Entertainment | K6: 3 | L6: 2 | M6: 2 | N6: 1824000000 | O6: 455900 | P6: 7300000 | Q6: 5500000 | R6: 87500000 | S6: 1000000 | T6: 2006 | U6: Sep | V6: 20 | W6: 28.1 | X6: 1366417754 | Y6: 5.36 | Z6: 471031528 | AA6: 20.593684 | AB6: 78.96288 | AC6: 539.51852 | AD6: 1269993.8 | AE6: 1364.3853 | AF6: 0.0010743243 | AG6: 49.324324 | AH6: 930.81761 | AI6: 20 | AJ6: 6844100 | AK6: 82000000 | AL6: 50000 | AM6: =youtube_stats_raw[[#This Row],[subscribers_for_last_30_days]] / youtube_stats_raw[[#This Row],[subscribers]] -> 0.0062893082 | AN6: =IF(AND(youtube_stats_raw[[#This Row],[upload_frequency]]>23.1077381,youtube_stats_raw[[#This Row],[ engagement_rate]]<=0),"High",IF(OR(youtube_stats_raw[[#This Row],[upload_frequency]]>23.1077381,youtube_stats_raw[[#This Row],[ engagement_rate]]<=0),"Medium","Low")) -> Medium | AO6: =DATE(T6, MATCH(U6,{"Jan","Feb","Mar","Apr","May","Jun","Jul","Aug","Sep","Oct","Nov","Dec"},0), V6) -> 38980 | AP6: =IF(youtube_stats_raw[[#This Row],[subscribers]]<70000000,"Micro",IF(youtube_stats_raw[[#This Row],[subscribers]]<128000000,"Mid",IF(youtube_stats_raw[[#This Row],[subscribers]]<186000000,"Macro","Mega"))) -> Macro | AQ6: =SUM((youtube_stats_raw[[#This Row],[lowest_yearly_earnings]] + youtube_stats_raw[[#This Row],[highest_yearly_earnings]])/2) -> 46500000 | AR6: =IF(youtube_stats_raw[[#This Row],[upload_frequency]]<=_xlfn.PERCENTILE.INC(AC:AC,0.2),"Very Low",IF(youtube_stats_raw[[#This Row],[upload_frequency]]<=_xlfn.PERCENTILE.INC(AC:AC,0.4),"Low",IF(youtube_stats_raw[[#This Row],[upload_frequency]]<=_xlfn.PERCENTILE.INC(AC:AC,0.6),"Medium",IF(youtube_stats_raw[[#This Row],[upload_frequency]]<=_xlfn.PERCENTILE.INC(AC:AC,0.8),"High","Very High")))) -> Very High
A7: 7 | B7: ýýý Kids Diana Show | C7: 112000000 | D7: 93247040539 | E7: People & Blogs | F7: ýýý Kids Diana Show | G7: 1111 | H7: United States | I7: US | J7: Entertainment | K7: 5 | L7: 3 | M7: 3 | N7: 731674000 | O7: 182900 | P7: 2900000 | Q7: 2200000 | R7: 35100000 | S7: 0 | T7: 2015 | U7: May | V7: 12 | W7: 88.2 | X7: 328239523 | Y7: 14.7 | Z7: 270663028 | AA7: 37.09024 | AB7: -95.712891 | AC7: 10.287037 | AD7: 83930730 | AE7: 100810.08 | AF7: 0.0012011105 | AG7: 31.100183 | AH7: 832.56286 | AI7: 11 | AJ7: 2717100 | AK7: 32900000 | AL7: 0 | AM7: =youtube_stats_raw[[#This Row],[subscribers_for_last_30_days]] / youtube_stats_raw[[#This Row],[subscribers]] -> 0 | AN7: =IF(AND(youtube_stats_raw[[#This Row],[upload_frequency]]>23.1077381,youtube_stats_raw[[#This Row],[ engagement_rate]]<=0),"High",IF(OR(youtube_stats_raw[[#This Row],[upload_frequency]]>23.1077381,youtube_stats_raw[[#This Row],[ engagement_rate]]<=0),"Medium","Low")) -> Medium | AO7: =DATE(T7, MATCH(U7,{"Jan","Feb","Mar","Apr","May","Jun","Jul","Aug","Sep","Oct","Nov","Dec"},0), V7) -> 42136 | AP7: =IF(youtube_stats_raw[[#This Row],[subscribers]]<70000000,"Micro",IF(youtube_stats_raw[[#This Row],[subscribers]]<128000000,"Mid",IF(youtube_stats_raw[[#This Row],[subscribers]]<186000000,"Macro","Mega"))) -> Mid | AQ7: =SUM((youtube_stats_raw[[#This Row],[lowest_yearly_earnings]] + youtube_stats_raw[[#This Row],[highest_yearly_earnings]])/2) -> 18650000 | AR7: =IF(youtube_stats_raw[[#This Row],[upload_frequency]]<=_xlfn.PERCENTILE.INC(AC:AC,0.2),"Very Low",IF(youtube_stats_raw[[#This Row],[upload_frequency]]<=_xlfn.PERCENTILE.INC(AC:AC,0.4),"Low",IF(youtube_stats_raw[[#This Row],[upload_frequency]]<=_xlfn.PERCENTILE.INC(AC:AC,0.6),"Medium",IF(youtube_stats_raw[[#This Row],[upload_frequency]]<=_xlfn.PERCENTILE.INC(AC:AC,0.8),"High","Very High")))) -> Medium
A8: 8 | B8: PewDiePie | C8: 111000000 | D8: 29058044447 | E8: Gaming | F8: PewDiePie | G8: 4716 | H8: Japan | I8: JP | J8: Entertainment | K8: 44 | L8: 1 | M8: 4 | N8: 39184000 | O8: 9800 | P8: 156700 | Q8: 117600 | R8: 1900000 | S8: 0 | T8: 2010 | U8: Apr | V8: 29 | W8: 63.2 | X8: 126226568 | Y8: 2.29 | Z8: 115782416 | AA8: 36.204824 | AB8: 138.25292 | AC8: 28.071429 | AD8: 6161587 | AE8: 23536.896 | AF8: 0.0038199405 | AG8: 5.3926547 | AH8: 261.78418 | AI8: 16 | AJ8: 146900 | AK8: 1782400 | AL8: 0 | AM8: =youtube_stats_raw[[#This Row],[subscribers_for_last_30_days]] / youtube_stats_raw[[#This Row],[subscribers]] -> 0 | AN8: =IF(AND(youtube_stats_raw[[#This Row],[upload_frequency]]>23.1077381,youtube_stats_raw[[#This Row],[ engagement_rate]]<=0),"High",IF(OR(youtube_stats_raw[[#This Row],[upload_frequency]]>23.1077381,youtube_stats_raw[[#This Row],[ engagement_rate]]<=0),"Medium","Low")) -> High | AO8: =DATE(T8, MATCH(U8,{"Jan","Feb","Mar","Apr","May","Jun","Jul","Aug","Sep","Oct","Nov","Dec"},0), V8) -> 40297 | AP8: =IF(youtube_stats_raw[[#This Row],[subscribers]]<70000000,"Micro",IF(youtube_stats_raw[[#This Row],[subscribers]]<128000000,"Mid",IF(youtube_stats_raw[[#This Row],[subscribers]]<186000000,"Macro","Mega"))) -> Mid | AQ8: =SUM((youtube_stats_raw[[#This Row],[lowest_yearly_earnings]] + youtube_stats_raw[[#This Row],[highest_yearly_earnings]])/2) -> 1008800 | AR8: =IF(youtube_stats_raw[[#This Row],[upload_frequency]]<=_xlfn.PERCENTILE.INC(AC:AC,0.2),"Very Low",IF(youtube_stats_raw[[#This Row],[upload_frequency]]<=_xlfn.PERCENTILE.INC(AC:AC,0.4),"Low",IF(youtube_stats_raw[[#This Row],[upload_frequency]]<=_xlfn.PERCENTILE.INC(AC:AC,0.6),"Medium",IF(youtube_stats_raw[[#This Row],[upload_frequency]]<=_xlfn.PERCENTILE.INC(AC:AC,0.8),"High","Very High")))) -> High
A9: 9 | B9: Like Nastya | C9: 106000000 | D9: 90479060027 | E9: People & Blogs | F9: Like Nastya Vlog | G9: 493 | H9: Russia | I9: RU | J9: People | K9: 630 | L9: 5 | M9: 25 | N9: 48947000 | O9: 12200 | P9: 195800 | Q9: 146800 | R9: 2300000 | S9: 100000 | T9: 2016 | U9: Jan | V9: 14 | W9: 81.9 | X9: 144373535 | Y9: 4.59 | Z9: 107683889 | AA9: 61.52401 | AB9: 105.31876 | AC9: 5.1354167 | AD9: 1.8352751e+08 | AE9: 215010.14 | AF9: 0.0011715418 | AG9: 2.1640366 | AH9: 853.57604 | AI9: 10 | AJ9: 183600 | AK9: 2153200 | AL9: 10000 | AM9: =youtube_stats_raw[[#This Row],[subscribers_for_last_30_days]] / youtube_stats_raw[[#This Row],[subscribers]] -> 0.00094339623 | AN9: =IF(AND(youtube_stats_raw[[#This Row],[upload_frequency]]>23.1077381,youtube_stats_raw[[#This Row],[ engagement_rate]]<=0),"High",IF(OR(youtube_stats_raw[[#This Row],[upload_frequency]]>23.1077381,youtube_stats_raw[[#This Row],[ engagement_rate]]<=0),"Medium","Low")) -> Low | AO9: =DATE(T9, MATCH(U9,{"Jan","Feb","Mar","Apr","May","Jun","Jul","Aug","Sep","Oct","Nov","Dec"},0), V9) -> 42383 | AP9: =IF(youtube_stats_raw[[#This Row],[subscribers]]<70000000,"Micro",IF(youtube_stats_raw[[#This Row],[subscribers]]<128000000,"Mid",IF(youtube_stats_raw[[#This Row],[subscribers]]<186000000,"Macro","Mega"))) -> Mid | AQ9: =SUM((youtube_stats_raw[[#This Row],[lowest_yearly_earnings]] + youtube_stats_raw[[#This Row],[highest_yearly_earnings]])/2) -> 1223400 | AR9: =IF(youtube_stats_raw[[#This Row],[upload_frequency]]<=_xlfn.PERCENTILE.INC(AC:AC,0.2),"Very Low",IF(youtube_stats_raw[[#This Row],[upload_frequency]]<=_xlfn.PERCENTILE.INC(AC:AC,0.4),"Low",IF(youtube_stats_raw[[#This Row],[upload_frequency]]<=_xlfn.PERCENTILE.INC(AC:AC,0.6),"Medium",IF(youtube_stats_raw[[#This Row],[upload_frequency]]<=_xlfn.PERCENTILE.INC(AC:AC,0.8),"High","Very High")))) -> Low
A10: 10 | B10: Vlad and Niki | C10: 98900000 | D10: 77180169894 | E10: Entertainment | F10: Vlad and Niki | G10: 574 | H10: United States | I10: US | J10: Entertainment | K10: 8 | L10: 5 | M10: 6 | N10: 580574000 | O10: 145100 | P10: 2300000 | Q10: 1700000 | R10: 27900000 | S10: 600000 | T10: 2018 | U10: Apr | V10: 23 | W10: 88.2 | X10: 328239523 | Y10: 14.7 | Z10: 270663028 | AA10: 37.09024 | AB10: -95.712891 | AC10: 7.9722222 | AD10: 1.3446023e+08 | AE10: 172299.65 | AF10: 0.0012814172 | AG10: 29.800401 | AH10: 780.38594 | AI10: 8 | AJ10: 2154900 | AK10: 26200000 | AL10: 75000 | AM10: =youtube_stats_raw[[#This Row],[subscribers_for_last_30_days]] / youtube_stats_raw[[#This Row],[subscribers]] -> 0.0060667341 | AN10: =IF(AND(youtube_stats_raw[[#This Row],[upload_frequency]]>23.1077381,youtube_stats_raw[[#This Row],[ engagement_rate]]<=0),"High",IF(OR(youtube_stats_raw[[#This Row],[upload_frequency]]>23.1077381,youtube_stats_raw[[#This Row],[ engagement_rate]]<=0),"Medium","Low")) -> Low | AO10: =DATE(T10, MATCH(U10,{"Jan","Feb","Mar","Apr","May","Jun","Jul","Aug","Sep","Oct","Nov","Dec"},0), V10) -> 43213 | AP10: =IF(youtube_stats_raw[[#This Row],[subscribers]]<70000000,"Micro",IF(youtube_stats_raw[[#This Row],[subscribers]]<128000000,"Mid",IF(youtube_stats_raw[[#This Row],[subscribers]]<186000000,"Macro","Mega"))) -> Mid | AQ10: =SUM((youtube_stats_raw[[#This Row],[lowest_yearly_earnings]] + youtube_stats_raw[[#This Row],[highest_yearly_earnings]])/2) -> 14800000 | AR10: =IF(youtube_stats_raw[[#This Row],[upload_frequency]]<=_xlfn.PERCENTILE.INC(AC:AC,0.2),"Very Low",IF(youtube_stats_raw[[#This Row],[upload_frequency]]<=_xlfn.PERCENTILE.INC(AC:AC,0.4),"Low",IF(youtube_stats_raw[[#This Row],[upload_frequency]]<=_xlfn.PERCENTILE.INC(AC:AC,0.6),"Medium",IF(youtube_stats_raw[[#This Row],[upload_frequency]]<=_xlfn.PERCENTILE.INC(AC:AC,0.8),"High","Very High")))) -> Medium
A11: 11 | B11: Zee Music Company | C11: 96700000 | D11: 57856289381 | E11: Music | F11: Zee Music Company | G11: 8548 | H11: India | I11: IN | J11: Music | K11: 12 | L11: 3 | M11: 2 | N11: 803613000 | O11: 200900 | P11: 3200000 | Q11: 2400000 | R11: 38600000 | S11: 1100000 | T11: 2014 | U11: Mar | V11: 12 | W11: 28.1 | X11: 1366417754 | Y11: 5.36 | Z11: 471031528 | AA11: 20.593684 | AB11: 78.96288 | AC11: 71.233333 | AD11: 6768400.7 | AE11: 11312.588 | AF11: 0.0016713827 | AG11: 55.309458 | AH11: 598.30703 | AI11: 12 | AJ11: 2999100 | AK11: 36200000 | AL11: 91666.667 | AM11: =youtube_stats_raw[[#This Row],[subscribers_for_last_30_days]] / youtube_stats_raw[[#This Row],[subscribers]] -> 0.011375388 | AN11: =IF(AND(youtube_stats_raw[[#This Row],[upload_frequency]]>23.1077381,youtube_stats_raw[[#This Row],[ engagement_rate]]<=0),"High",IF(OR(youtube_stats_raw[[#This Row],[upload_frequency]]>23.1077381,youtube_stats_raw[[#This Row],[ engagement_rate]]<=0),"Medium","Low")) -> Medium | AO11: =DATE(T11, MATCH(U11,{"Jan","Feb","Mar","Apr","May","Jun","Jul","Aug","Sep","Oct","Nov","Dec"},0), V11) -> 41710 | AP11: =IF(youtube_stats_raw[[#This Row],[subscribers]]<70000000,"Micro",IF(youtube_stats_raw[[#This Row],[subscribers]]<128000000,"Mid",IF(youtube_stats_raw[[#This Row],[subscribers]]<186000000,"Macro","Mega"))) -> Mid | AQ11: =SUM((youtube_stats_raw[[#This Row],[lowest_yearly_earnings]] + youtube_stats_raw[[#This Row],[highest_yearly_earnings]])/2) -> 20500000 | AR11: =IF(youtube_stats_raw[[#This Row],[upload_frequency]]<=_xlfn.PERCENTILE.INC(AC:AC,0.2),"Very Low",IF(youtube_stats_raw[[#This Row],[upload_frequency]]<=_xlfn.PERCENTILE.INC(AC:AC,0.4),"Low",IF(youtube_stats_raw[[#This Row],[upload_frequency]]<=_xlfn.PERCENTILE.INC(AC:AC,0.6),"Medium",IF(youtube_stats_raw[[#This Row],[upload_frequency]]<=_xlfn.PERCENTILE.INC(AC:AC,0.8),"High","Very High")))) -> Very High
A12: 12 | B12: WWE | C12: 96000000 | D12: 77428473662 | E12: Sports | F12: WWE | G12: 70127 | H12: United States | I12: US | J12: Sports | K12: 7 | L12: 6 | M12: 1 | N12: 714614000 | O12: 178700 | P12: 2900000 | Q12: 2100000 | R12: 34300000 | S12: 600000 | T12: 2007 | U12: May | V12: 11 | W12: 88.2 | X12: 328239523 | Y12: 14.7 | Z12: 270663028 | AA12: 37.09024 | AB12: -95.712891 | AC12: 343.7598 | AD12: 1104117.9 | AE12: 1368.9449 | AF12: 0.001239854 | AG12: 37.453922 | AH12: 806.5466 | AI12: 19 | AJ12: 2721300 | AK12: 32200000 | AL12: 31578.947 | AM12: =youtube_stats_raw[[#This Row],[subscribers_for_last_30_days]] / youtube_stats_raw[[#This Row],[subscribers]] -> 0.00625 | AN12: =IF(AND(youtube_stats_raw[[#This Row],[upload_frequency]]>23.1077381,youtube_stats_raw[[#This Row],[ engagement_rate]]<=0),"High",IF(OR(youtube_stats_raw[[#This Row],[upload_frequency]]>23.1077381,youtube_stats_raw[[#This Row],[ engagement_rate]]<=0),"Medium","Low")) -> Medium | AO12: =DATE(T12, MATCH(U12,{"Jan","Feb","Mar","Apr","May","Jun","Jul","Aug","Sep","Oct","Nov","Dec"},0), V12) -> 39213 | AP12: =IF(youtube_stats_raw[[#This Row],[subscribers]]<70000000,"Micro",IF(youtube_stats_raw[[#This Row],[subscribers]]<128000000,"Mid",IF(youtube_stats_raw[[#This Row],[subscribers]]<186000000,"Macro","Mega"))) -> Mid | AQ12: =SUM((youtube_stats_raw[[#This Row],[lowest_yearly_earnings]] + youtube_stats_raw[[#This Row],[highest_yearly_earnings]])/2) -> 18200000 | AR12: =IF(youtube_stats_raw[[#This Row],[upload_frequency]]<=_xlfn.PERCENTILE.INC(AC:AC,0.2),"Very Low",IF(youtube_stats_raw[[#This Row],[upload_frequency]]<=_xlfn.PERCENTILE.INC(AC:AC,0.4),"Low",IF(youtube_stats_raw[[#This Row],[upload_frequency]]<=_xlfn.PERCENTILE.INC(AC:AC,0.6),"Medium",IF(youtube_stats_raw[[#This Row],[upload_frequency]]<=_xlfn.PERCENTILE.INC(AC:AC,0.8),"High","Very High")))) -> Very High
A13: 14 | B13: BLACKPINK | C13: 89800000 | D13: 32144597566 | E13: People & Blogs | F13: BLACKPINK | G13: 543 | H13: South Korea | I13: KR | J13: Music | K13: 32 | L13: 1 | M13: 3 | N13: 498930000 | O13: 124700 | P13: 2000000 | Q13: 1500000 | R13: 23900000 | S13: 700000 | T13: 2016 | U13: Jun | V13: 29 | W13: 94.3 | X13: 51709098 | Y13: 4.15 | Z13: 42106719 | AA13: 35.907757 | AB13: 127.76692 | AC13: 5.65625 | AD13: 59198154 | AE13: 165377.53 | AF13: 0.0027936265 | AG13: 62.218853 | AH13: 357.95766 | AI13: 10 | AJ13: 1875300 | AK13: 22400000 | AL13: 70000 | AM13: =youtube_stats_raw[[#This Row],[subscribers_for_last_30_days]] / youtube_stats_raw[[#This Row],[subscribers]] -> 0.0077951002 | AN13: =IF(AND(youtube_stats_raw[[#This Row],[upload_frequency]]>23.1077381,youtube_stats_raw[[#This Row],[ engagement_rate]]<=0),"High",IF(OR(youtube_stats_raw[[#This Row],[upload_frequency]]>23.1077381,youtube_stats_raw[[#This Row],[ engagement_rate]]<=0),"Medium","Low")) -> Low | AO13: =DATE(T13, MATCH(U13,{"Jan","Feb","Mar","Apr","May","Jun","Jul","Aug","Sep","Oct","Nov","Dec"},0), V13) -> 42550 | AP13: =IF(youtube_stats_raw[[#This Row],[subscribers]]<70000000,"Micro",IF(youtube_stats_raw[[#This Row],[subscribers]]<128000000,"Mid",IF(youtube_stats_raw[[#This Row],[subscribers]]<186000000,"Macro","Mega"))) -> Mid | AQ13: =SUM((youtube_stats_raw[[#This Row],[lowest_yearly_earnings]] + youtube_stats_raw[[#This Row],[highest_yearly_earnings]])/2) -> 12700000 | AR13: =IF(youtube_stats_raw[[#This Row],[upload_frequency]]<=_xlfn.PERCENTILE.INC(AC:AC,0.2),"Very Low",IF(youtube_stats_raw[[#This Row],[upload_frequency]]<=_xlfn.PERCENTILE.INC(AC:AC,0.4),"Low",IF(youtube_stats_raw[[#This Row],[upload_frequency]]<=_xlfn.PERCENTILE.INC(AC:AC,0.6),"Medium",IF(youtube_stats_raw[[#This Row],[upload_frequency]]<=_xlfn.PERCENTILE.INC(AC:AC,0.8),"High","Very High")))) -> Medium
A14: 16 | B14: Sony SAB | C14: 83000000 | D14: 101000000000 | E14: Shows | F14: Sony SAB | G14: 71270 | H14: India | I14: IN | J14: Entertainment | K14: 4 | L14: 5 | M14: 7 | N14: 1657000000 | O14: 414300 | P14: 6600000 | Q14: 5000000 | R14: 79600000 | S14: 1100000 | T14: 2007 | U14: Aug | V14: 4 | W14: 28.1 | X14: 1366417754 | Y14: 5.36 | Z14: 471031528 | AA14: 20.593684 | AB14: 78.96288 | AC14: 349.36275 | AD14: 1417146.1 | AE14: 1164.5854 | AF14: 0.00082178218 | AG14: 65.346535 | AH14: 1216.8675 | AI14: 19 | AJ14: 6185700 | AK14: 74600000 | AL14: 57894.737 | AM14: =youtube_stats_raw[[#This Row],[subscribers_for_last_30_days]] / youtube_stats_raw[[#This Row],[subscribers]] -> 0.013253012 | AN14: =IF(AND(youtube_stats_raw[[#This Row],[upload_frequency]]>23.1077381,youtube_stats_raw[[#This Row],[ engagement_rate]]<=0),"High",IF(OR(youtube_stats_raw[[#This Row],[upload_frequency]]>23.1077381,youtube_stats_raw[[#This Row],[ engagement_rate]]<=0),"Medium","Low")) -> Medium | AO14: =DATE(T14, MATCH(U14,{"Jan","Feb","Mar","Apr","May","Jun","Jul","Aug","Sep","Oct","Nov","Dec"},0), V14) -> 39298 | AP14: =IF(youtube_stats_raw[[#This Row],[subscribers]]<70000000,"Micro",IF(youtube_stats_raw[[#This Row],[subscribers]]<128000000,"Mid",IF(youtube_stats_raw[[#This Row],[subscribers]]<186000000,"Macro","Mega"))) -> Mid | AQ14: =SUM((youtube_stats_raw[[#This Row],[lowest_yearly_earnings]] + youtube_stats_raw[[#This Row],[highest_yearly_earnings]])/2) -> 42300000 | AR14: =IF(youtube_stats_raw[[#This Row],[upload_frequency]]<=_xlfn.PERCENTILE.INC(AC:AC,0.2),"Very Low",IF(youtube_stats_raw[[#This Row],[upload_frequency]]<=_xlfn.PERCENTILE.INC(AC:AC,0.4),"Low",IF(youtube_stats_raw[[#This Row],[upload_frequency]]<=_xlfn.PERCENTILE.INC(AC:AC,0.6),"Medium",IF(youtube_stats_raw[[#This Row],[upload_frequency]]<=_xlfn.PERCENTILE.INC(AC:AC,0.8),"High","Very High")))) -> Very High
A15: 17 | B15: 5-Minute Crafts | C15: 80100000 | D15: 26236790209 | E15: Howto & Style | F15: 5-Minute Crafts 2.0 | G15: 1 | H15: United Kingdom | I15: GB | J15: Entertainment | K15: 4057901 | L15: 4797 | M15: 6781 | N15: 1 | O15: 0 | P15: 0 | Q15: 0 | R15: 0 | S15: 0 | T15: 2020 | U15: Jul | V15: 27 | W15: 60 | X15: 66834405 | Y15: 3.85 | Z15: 55908316 | AA15: 55.378051 | AB15: -3.435973 | AC15: 0.020833333 | AD15: 26236790209 | AE15: 80100000 | AF15: 0.0030529649 | AG15: 0 | AH15: 327.55044 | AI15: 6 | AJ15: 0 | AK15: 0 | AL15: 0 | AM15: =youtube_stats_raw[[#This Row],[subscribers_for_last_30_days]] / youtube_stats_raw[[#This Row],[subscribers]] -> 0 | AN15: =IF(AND(youtube_stats_raw[[#This Row],[upload_frequency]]>23.1077381,youtube_stats_raw[[#This Row],[ engagement_rate]]<=0),"High",IF(OR(youtube_stats_raw[[#This Row],[upload_frequency]]>23.1077381,youtube_stats_raw[[#This Row],[ engagement_rate]]<=0),"Medium","Low")) -> Medium | AO15: =DATE(T15, MATCH(U15,{"Jan","Feb","Mar","Apr","May","Jun","Jul","Aug","Sep","Oct","Nov","Dec"},0), V15) -> 44039 | AP15: =IF(youtube_stats_raw[[#This Row],[subscribers]]<70000000,"Micro",IF(youtube_stats_raw[[#This Row],[subscribers]]<128000000,"Mid",IF(youtube_stats_raw[[#This Row],[subscribers]]<186000000,"Macro","Mega"))) -> Mid | AQ15: =SUM((youtube_stats_raw[[#This Row],[lowest_yearly_earnings]] + youtube_stats_raw[[#This Row],[highest_yearly_earnings]])/2) -> 0 | AR15: =IF(youtube_stats_raw[[#This Row],[upload_frequency]]<=_xlfn.PERCENTILE.INC(AC:AC,0.2),"Very Low",IF(youtube_stats_raw[[#This Row],[upload_frequency]]<=_xlfn.PERCENTILE.INC(AC:AC,0.4),"Low",IF(youtube_stats_raw[[#This Row],[upload_frequency]]<=_xlfn.PERCENTILE.INC(AC:AC,0.6),"Medium",IF(youtube_stats_raw[[#This Row],[upload_frequency]]<=_xlfn.PERCENTILE.INC(AC:AC,0.8),"High","Very High")))) -> Very Low
A16: 18 | B16: BANGTANTV | C16: 75600000 | D16: 20826993957 | E16: Music | F16: BANGTANTV | G16: 2281 | H16: South Korea | I16: KR | J16: Music | K16: 112 | L16: 2 | M16: 4 | N16: 168290000 | O16: 42100 | P16: 673200 | Q16: 504900 | R16: 8100000 | S16: 400000 | T16: 2012 | U16: Dec | V16: 17 | W16: 94.3 | X16: 51709098 | Y16: 4.15 | Z16: 42106719 | AA16: 35.907757 | AB16: 127.76692 | AC16: 15.840278 | AD16: 9130641.8 | AE16: 33143.358 | AF16: 0.0036299045 | AG16: 32.323436 | AH16: 275.48934 | AI16: 14 | AJ16: 631100 | AK16: 7595100 | AL16: 28571.429 | AM16: =youtube_stats_raw[[#This Row],[subscribers_for_last_30_days]] / youtube_stats_raw[[#This Row],[subscribers]] -> 0.0052910053 | AN16: =IF(AND(youtube_stats_raw[[#This Row],[upload_frequency]]>23.1077381,youtube_stats_raw[[#This Row],[ engagement_rate]]<=0),"High",IF(OR(youtube_stats_raw[[#This Row],[upload_frequency]]>23.1077381,youtube_stats_raw[[#This Row],[ engagement_rate]]<=0),"Medium","Low")) -> Low | AO16: =DATE(T16, MATCH(U16,{"Jan","Feb","Mar","Apr","May","Jun","Jul","Aug","Sep","Oct","Nov","Dec"},0), V16) -> 41260 | AP16: =IF(youtube_stats_raw[[#This Row],[subscribers]]<70000000,"Micro",IF(youtube_stats_raw[[#This Row],[subscribers]]<128000000,"Mid",IF(youtube_stats_raw[[#This Row],[subscribers]]<186000000,"Macro","Mega"))) -> Mid | AQ16: =SUM((youtube_stats_raw[[#This Row],[lowest_yearly_earnings]] + youtube_stats_raw[[#This Row],[highest_yearly_earnings]])/2) -> 4302450 | AR16: =IF(youtube_stats_raw[[#This Row],[upload_frequency]]<=_xlfn.PERCENTILE.INC(AC:AC,0.2),"Very Low",IF(youtube_stats_raw[[#This Row],[upload_frequency]]<=_xlfn.PERCENTILE.INC(AC:AC,0.4),"Low",IF(youtube_stats_raw[[#This Row],[upload_frequency]]<=_xlfn.PERCENTILE.INC(AC:AC,0.6),"Medium",IF(youtube_stats_raw[[#This Row],[upload_frequency]]<=_xlfn.PERCENTILE.INC(AC:AC,0.8),"High","Very High")))) -> High
A17: 19 | B17: Sports | C17: 75000000 | D17: 0 | E17: Entertainment | F17: sports | G17: 3 | H17: United States | I17: US | J17: Entertainment | K17: 3898122 | L17: 6266 | M17: 5395 | N17: 16 | O17: 0 | P17: 0 | Q17: 0 | R17: 1 | S17: 0 | T17: 2006 | U17: Jan | V17: 30 | W17: 88.2 | X17: 328239523 | Y17: 14.7 | Z17: 270663028 | AA17: 37.09024 | AB17: -95.712891 | AC17: 0.013888889 | AD17: 0 | AE17: 25000000 | AF17: 0 | AG17: #NUM! | AH17: 0 | AI17: 20 | AJ17: 0 | AK17: 1 | AL17: 0 | AM17: =youtube_stats_raw[[#This Row],[subscribers_for_last_30_days]] / youtube_stats_raw[[#This Row],[subscribers]] -> 0 | AN17: =IF(AND(youtube_stats_raw[[#This Row],[upload_frequency]]>23.1077381,youtube_stats_raw[[#This Row],[ engagement_rate]]<=0),"High",IF(OR(youtube_stats_raw[[#This Row],[upload_frequency]]>23.1077381,youtube_stats_raw[[#This Row],[ engagement_rate]]<=0),"Medium","Low")) -> Medium | AO17: =DATE(T17, MATCH(U17,{"Jan","Feb","Mar","Apr","May","Jun","Jul","Aug","Sep","Oct","Nov","Dec"},0), V17) -> 38747 | AP17: =IF(youtube_stats_raw[[#This Row],[subscribers]]<70000000,"Micro",IF(youtube_stats_raw[[#This Row],[subscribers]]<128000000,"Mid",IF(youtube_stats_raw[[#This Row],[subscribers]]<186000000,"Macro","Mega"))) -> Mid | AQ17: =SUM((youtube_stats_raw[[#This Row],[lowest_yearly_earnings]] + youtube_stats_raw[[#This Row],[highest_yearly_earnings]])/2) -> 0.5 | AR17: =IF(youtube_stats_raw[[#This Row],[upload_frequency]]<=_xlfn.PERCENTILE.INC(AC:AC,0.2),"Very Low",IF(youtube_stats_raw[[#This Row],[upload_frequency]]<=_xlfn.PERCENTILE.INC(AC:AC,0.4),"Low",IF(youtube_stats_raw[[#This Row],[upload_frequency]]<=_xlfn.PERCENTILE.INC(AC:AC,0.6),"Medium",IF(youtube_stats_raw[[#This Row],[upload_frequency]]<=_xlfn.PERCENTILE.INC(AC:AC,0.8),"High","Very High")))) -> Very Low
A18: 20 | B18: Justin Bieber | C18: 71600000 | D18: 30608119724 | E18: Music | F18: Justin Bieber | G18: 249 | H18: Canada | I18: CA | J18: Music | K18: 38 | L18: 1 | M18: 6 | N18: 176326000 | O18: 44100 | P18: 705300 | Q18: 529000 | R18: 8500000 | S18: 100000 | T18: 2007 | U18: Jan | V18: 15 | W18: 68.9 | X18: 36991981 | Y18: 5.56 | Z18: 30628482 | AA18: 56.130366 | AB18: -106.34677 | AC18: 1.2205882 | AD18: 1.2292418e+08 | AE18: 287550.2 | AF18: 0.0023392486 | AG18: 23.042905 | AH18: 427.48771 | AI18: 19 | AJ18: 661200 | AK18: 7971000 | AL18: 5263.1579 | AM18: =youtube_stats_raw[[#This Row],[subscribers_for_last_30_days]] / youtube_stats_raw[[#This Row],[subscribers]] -> 0.001396648 | AN18: =IF(AND(youtube_stats_raw[[#This Row],[upload_frequency]]>23.1077381,youtube_stats_raw[[#This Row],[ engagement_rate]]<=0),"High",IF(OR(youtube_stats_raw[[#This Row],[upload_frequency]]>23.1077381,youtube_stats_raw[[#This Row],[ engagement_rate]]<=0),"Medium","Low")) -> Low | AO18: =DATE(T18, MATCH(U18,{"Jan","Feb","Mar","Apr","May","Jun","Jul","Aug","Sep","Oct","Nov","Dec"},0), V18) -> 39097 | AP18: =IF(youtube_stats_raw[[#This Row],[subscribers]]<70000000,"Micro",IF(youtube_stats_raw[[#This Row],[subscribers]]<128000000,"Mid",IF(youtube_stats_raw[[#This Row],[subscribers]]<186000000,"Macro","Mega"))) -> Mid | AQ18: =SUM((youtube_stats_raw[[#This Row],[lowest_yearly_earnings]] + youtube_stats_raw[[#This Row],[highest_yearly_earnings]])/2) -> 4514500 | AR18: =IF(youtube_stats_raw[[#This Row],[upload_frequency]]<=_xlfn.PERCENTILE.INC(AC:AC,0.2),"Very Low",IF(youtube_stats_raw[[#This Row],[upload_frequency]]<=_xlfn.PERCENTILE.INC(AC:AC,0.4),"Low",IF(youtube_stats_raw[[#This Row],[upload_frequency]]<=_xlfn.PERCENTILE.INC(AC:AC,0.6),"Medium",IF(youtube_stats_raw[[#This Row],[upload_frequency]]<=_xlfn.PERCENTILE.INC(AC:AC,0.8),"High","Very High")))) -> Very Low
A19: 21 | B19: HYBE LABELS | C19: 71300000 | D19: 28634566938 | E19: Music | F19: HYBE LABELS | G19: 1337 | H19: South Korea | I19: KR | J19: Music | K19: 46 | L19: 3 | M19: 5 | N19: 598173000 | O19: 149500 | P19: 2400000 | Q19: 1800000 | R19: 28700000 | S19: 900000 | T19: 2008 | U19: Jun | V19: 4 | W19: 94.3 | X19: 51709098 | Y19: 4.15 | Z19: 42106719 | AA19: 35.907757 | AB19: 127.76692 | AC19: 6.9635417 | AD19: 21417028 | AE19: 53328.347 | AF19: 0.0024899975 | AG19: 83.814783 | AH19: 401.60683 | AI19: 18 | AJ19: 2250500 | AK19: 26900000 | AL19: 50000 | AM19: =youtube_stats_raw[[#This Row],[subscribers_for_last_30_days]] / youtube_stats_raw[[#This Row],[subscribers]] -> 0.012622721 | AN19: =IF(AND(youtube_stats_raw[[#This Row],[upload_frequency]]>23.1077381,youtube_stats_raw[[#This Row],[ engagement_rate]]<=0),"High",IF(OR(youtube_stats_raw[[#This Row],[upload_frequency]]>23.1077381,youtube_stats_raw[[#This Row],[ engagement_rate]]<=0),"Medium","Low")) -> Low | AO19: =DATE(T19, MATCH(U19,{"Jan","Feb","Mar","Apr","May","Jun","Jul","Aug","Sep","Oct","Nov","Dec"},0), V19) -> 39603 | AP19: =IF(youtube_stats_raw[[#This Row],[subscribers]]<70000000,"Micro",IF(youtube_stats_raw[[#This Row],[subscribers]]<128000000,"Mid",IF(youtube_stats_raw[[#This Row],[subscribers]]<186000000,"Macro","Mega"))) -> Mid | AQ19: =SUM((youtube_stats_raw[[#This Row],[lowest_yearly_earnings]] + youtube_stats_raw[[#This Row],[highest_yearly_earnings]])/2) -> 15250000 | AR19: =IF(youtube_stats_raw[[#This Row],[upload_frequency]]<=_xlfn.PERCENTILE.INC(AC:AC,0.2),"Very Low",IF(youtube_stats_raw[[#This Row],[upload_frequency]]<=_xlfn.PERCENTILE.INC(AC:AC,0.4),"Low",IF(youtube_stats_raw[[#This Row],[upload_frequency]]<=_xlfn.PERCENTILE.INC(AC:AC,0.6),"Medium",IF(youtube_stats_raw[[#This Row],[upload_frequency]]<=_xlfn.PERCENTILE.INC(AC:AC,0.8),"High","Very High")))) -> Medium
A20: 22 | B20: Zee TV | C20: 70500000 | D20: 73139054467 | E20: Entertainment | F20: Zee TV | G20: 129204 | H20: India | I20: IN | J20: Entertainment | K20: 9 | L20: 6 | M20: 8 | N20: 1707000000 | O20: 426800 | P20: 6800000 | Q20: 5100000 | R20: 81900000 | S20: 900000 | T20: 2005 | U20: Dec | V20: 11 | W20: 28.1 | X20: 1366417754 | Y20: 5.36 | Z20: 471031528 | AA20: 20.593684 | AB20: 78.96288 | AC20: 566.68421 | AD20: 566074.23 | AE20: 545.64874 | AF20: 0.0009639173 | AG20: 92.973584 | AH20: 1037.4334 | AI20: 21 | AJ20: 6373200 | AK20: 76800000 | AL20: 42857.143 | AM20: =youtube_stats_raw[[#This Row],[subscribers_for_last_30_days]] / youtube_stats_raw[[#This Row],[subscribers]] -> 0.012765957 | AN20: =IF(AND(youtube_stats_raw[[#This Row],[upload_frequency]]>23.1077381,youtube_stats_raw[[#This Row],[ engagement_rate]]<=0),"High",IF(OR(youtube_stats_raw[[#This Row],[upload_frequency]]>23.1077381,youtube_stats_raw[[#This Row],[ engagement_rate]]<=0),"Medium","Low")) -> Medium | AO20: =DATE(T20, MATCH(U20,{"Jan","Feb","Mar","Apr","May","Jun","Jul","Aug","Sep","Oct","Nov","Dec"},0), V20) -> 38697 | AP20: =IF(youtube_stats_raw[[#This Row],[subscribers]]<70000000,"Micro",IF(youtube_stats_raw[[#This Row],[subscribers]]<128000000,"Mid",IF(youtube_stats_raw[[#This Row],[subscribers]]<186000000,"Macro","Mega"))) -> Mid | AQ20: =SUM((youtube_stats_raw[[#This Row],[lowest_yearly_earnings]] + youtube_stats_raw[[#This Row],[highest_yearly_earnings]])/2) -> 43500000 | AR20: =IF(youtube_stats_raw[[#This Row],[upload_frequency]]<=_xlfn.PERCENTILE.INC(AC:AC,0.2),"Very Low",IF(youtube_stats_raw[[#This Row],[upload_frequency]]<=_xlfn.PERCENTILE.INC(AC:AC,0.4),"Low",IF(youtube_stats_raw[[#This Row],[upload_frequency]]<=_xlfn.PERCENTILE.INC(AC:AC,0.6),"Medium",IF(youtube_stats_raw[[#This Row],[upload_frequency]]<=_xlfn.PERCENTILE.INC(AC:AC,0.8),"High","Very High")))) -> Very High
A21: 23 | B21: Pinkfong Baby Shark - Kids' Songs & Stories | C21: 68200000 | D21: 38843229963 | E21: Education | F21: Pinkfong Baby Shark - Kids' Songs & Stories | G21: 2865 | H21: United States | I21: US | J21: Education | K21: 23 | L21: 8 | M21: 2 | N21: 473387000 | O21: 118300 | P21: 1900000 | Q21: 1400000 | R21: 22700000 | S21: 600000 | T21: 2011 | U21: Dec | V21: 14 | W21: 88.2 | X21: 328239523 | Y21: 14.7 | Z21: 270663028 | AA21: 37.09024 | AB21: -95.712891 | AC21: 18.365385 | AD21: 13557846 | AE21: 23804.538 | AF21: 0.0017557757 | AG21: 48.914573 | AH21: 569.54883 | AI21: 15 | AJ21: 1781700 | AK21: 21300000 | AL21: 40000 | AM21: =youtube_stats_raw[[#This Row],[subscribers_for_last_30_days]] / youtube_stats_raw[[#This Row],[subscribers]] -> 0.008797654 | AN21: =IF(AND(youtube_stats_raw[[#This Row],[upload_frequency]]>23.1077381,youtube_stats_raw[[#This Row],[ engagement_rate]]<=0),"High",IF(OR(youtube_stats_raw[[#This Row],[upload_frequency]]>23.1077381,youtube_stats_raw[[#This Row],[ engagement_rate]]<=0),"Medium","Low")) -> Low | AO21: =DATE(T21, MATCH(U21,{"Jan","Feb","Mar","Apr","May","Jun","Jul","Aug","Sep","Oct","Nov","Dec"},0), V21) -> 40891 | AP21: =IF(youtube_stats_raw[[#This Row],[subscribers]]<70000000,"Micro",IF(youtube_stats_raw[[#This Row],[subscribers]]<128000000,"Mid",IF(youtube_stats_raw[[#This Row],[subscribers]]<186000000,"Macro","Mega"))) -> Micro | AQ21: =SUM((youtube_stats_raw[[#This Row],[lowest_yearly_earnings]] + youtube_stats_raw[[#This Row],[highest_yearly_earnings]])/2) -> 12050000 | AR21: =IF(youtube_stats_raw[[#This Row],[upload_frequency]]<=_xlfn.PERCENTILE.INC(AC:AC,0.2),"Very Low",IF(youtube_stats_raw[[#This Row],[upload_frequency]]<=_xlfn.PERCENTILE.INC(AC:AC,0.4),"Low",IF(youtube_stats_raw[[#This Row],[upload_frequency]]<=_xlfn.PERCENTILE.INC(AC:AC,0.6),"Medium",IF(youtube_stats_raw[[#This Row],[upload_frequency]]<=_xlfn.PERCENTILE.INC(AC:AC,0.8),"High","Very High")))) -> High
A22: 24 | B22: Canal KondZilla | C22: 66500000 | D22: 36775585925 | E22: Music | F22: Canal KondZilla | G22: 2572 | H22: Brazil | I22: BR | J22: Music | K22: 25 | L22: 1 | M22: 7 | N22: 447223000 | O22: 0 | P22: 0 | Q22: 0 | R22: 0 | S22: 0 | T22: 2012 | U22: Mar | V22: 21 | W22: 51.3 | X22: 212559417 | Y22: 12.08 | Z22: 183241641 | AA22: -14.235004 | AB22: -51.92528 | AC22: 17.861111 | AD22: 14298439 | AE22: 25855.365 | AF22: 0.0018082649 | AG22: 0 | AH22: 553.01633 | AI22: 14 | AJ22: 0 | AK22: 0 | AL22: 0 | AM22: =youtube_stats_raw[[#This Row],[subscribers_for_last_30_days]] / youtube_stats_raw[[#This Row],[subscribers]] -> 0 | AN22: =IF(AND(youtube_stats_raw[[#This Row],[upload_frequency]]>23.1077381,youtube_stats_raw[[#This Row],[ engagement_rate]]<=0),"High",IF(OR(youtube_stats_raw[[#This Row],[upload_frequency]]>23.1077381,youtube_stats_raw[[#This Row],[ engagement_rate]]<=0),"Medium","Low")) -> Medium | AO22: =DATE(T22, MATCH(U22,{"Jan","Feb","Mar","Apr","May","Jun","Jul","Aug","Sep","Oct","Nov","Dec"},0), V22) -> 40989 | AP22: =IF(youtube_stats_raw[[#This Row],[subscribers]]<70000000,"Micro",IF(youtube_stats_raw[[#This Row],[subscribers]]<128000000,"Mid",IF(youtube_stats_raw[[#This Row],[subscribers]]<186000000,"Macro","Mega"))) -> Micro | AQ22: =SUM((youtube_stats_raw[[#This Row],[lowest_yearly_earnings]] + youtube_stats_raw[[#This Row],[highest_yearly_earnings]])/2) -> 0 | AR22: =IF(youtube_stats_raw[[#This Row],[upload_frequency]]<=_xlfn.PERCENTILE.INC(AC:AC,0.2),"Very Low",IF(youtube_stats_raw[[#This Row],[upload_frequency]]<=_xlfn.PERCENTILE.INC(AC:AC,0.4),"Low",IF(youtube_stats_raw[[#This Row],[upload_frequency]]<=_xlfn.PERCENTILE.INC(AC:AC,0.6),"Medium",IF(youtube_stats_raw[[#This Row],[upload_frequency]]<=_xlfn.PERCENTILE.INC(AC:AC,0.8),"High","Very High")))) -> High
A23: 25 | B23: ChuChu TV Nursery Rhymes & Kids Songs | C23: 65900000 | D23: 45757850229 | E23: Education | F23: ChuChu TV Nursery Rhymes & Kids Songs | G23: 633 | H23: India | I23: IN | J23: Education | K23: 18 | L23: 7 | M23: 3 | N23: 420292000 | O23: 105100 | P23: 1700000 | Q23: 1300000 | R23: 20200000 | S23: 500000 | T23: 2013 | U23: Feb | V23: 9 | W23: 28.1 | X23: 1366417754 | Y23: 5.36 | Z23: 471031528 | AA23: 20.593684 | AB23: 78.96288 | AC23: 4.7954545 | AD23: 72287283 | AE23: 104107.42 | AF23: 0.00144019 | AG23: 37.152095 | AH23: 694.35281 | AI23: 13 | AJ23: 1594900 | AK23: 18900000 | AL23: 38461.538 | AM23: =youtube_stats_raw[[#This Row],[subscribers_for_last_30_days]] / youtube_stats_raw[[#This Row],[subscribers]] -> 0.0075872534 | AN23: =IF(AND(youtube_stats_raw[[#This Row],[upload_frequency]]>23.1077381,youtube_stats_raw[[#This Row],[ engagement_rate]]<=0),"High",IF(OR(youtube_stats_raw[[#This Row],[upload_frequency]]>23.1077381,youtube_stats_raw[[#This Row],[ engagement_rate]]<=0),"Medium","Low")) -> Low | AO23: =DATE(T23, MATCH(U23,{"Jan","Feb","Mar","Apr","May","Jun","Jul","Aug","Sep","Oct","Nov","Dec"},0), V23) -> 41314 | AP23: =IF(youtube_stats_raw[[#This Row],[subscribers]]<70000000,"Micro",IF(youtube_stats_raw[[#This Row],[subscribers]]<128000000,"Mid",IF(youtube_stats_raw[[#This Row],[subscribers]]<186000000,"Macro","Mega"))) -> Micro | AQ23: =SUM((youtube_stats_raw[[#This Row],[lowest_yearly_earnings]] + youtube_stats_raw[[#This Row],[highest_yearly_earnings]])/2) -> 10750000 | AR23: =IF(youtube_stats_raw[[#This Row],[upload_frequency]]<=_xlfn.PERCENTILE.INC(AC:AC,0.2),"Very Low",IF(youtube_stats_raw[[#This Row],[upload_frequency]]<=_xlfn.PERCENTILE.INC(AC:AC,0.4),"Low",IF(youtube_stats_raw[[#This Row],[upload_frequency]]<=_xlfn.PERCENTILE.INC(AC:AC,0.6),"Medium",IF(youtube_stats_raw[[#This Row],[upload_frequency]]<=_xlfn.PERCENTILE.INC(AC:AC,0.8),"High","Very High")))) -> Low
A24: 26 | B24: Shemaroo Filmi Gaane | C24: 65600000 | D24: 28648024439 | E24: Music | F24: Shemaroo Filmi Gaane | G24: 8502 | H24: India | I24: IN | J24: Music | K24: 47 | L24: 8 | M24: 8 | N24: 254961000 | O24: 63700 | P24: 1000000 | Q24: 764900 | R24: 12200000 | S24: 400000 | T24: 2010 | U24: Jun | V24: 11 | W24: 28.1 | X24: 1366417754 | Y24: 5.36 | Z24: 471031528 | AA24: 20.593684 | AB24: 78.96288 | AC24: 50.607143 | AD24: 3369563 | AE24: 7715.8316 | AF24: 0.0022898612 | AG24: 34.906421 | AH24: 436.70769 | AI24: 16 | AJ24: 936300 | AK24: 11435100 | AL24: 25000 | AM24: =youtube_stats_raw[[#This Row],[subscribers_for_last_30_days]] / youtube_stats_raw[[#This Row],[subscribers]] -> 0.006097561 | AN24: =IF(AND(youtube_stats_raw[[#This Row],[upload_frequency]]>23.1077381,youtube_stats_raw[[#This Row],[ engagement_rate]]<=0),"High",IF(OR(youtube_stats_raw[[#This Row],[upload_frequency]]>23.1077381,youtube_stats_raw[[#This Row],[ engagement_rate]]<=0),"Medium","Low")) -> Medium | AO24: =DATE(T24, MATCH(U24,{"Jan","Feb","Mar","Apr","May","Jun","Jul","Aug","Sep","Oct","Nov","Dec"},0), V24) -> 40340 | AP24: =IF(youtube_stats_raw[[#This Row],[subscribers]]<70000000,"Micro",IF(youtube_stats_raw[[#This Row],[subscribers]]<128000000,"Mid",IF(youtube_stats_raw[[#This Row],[subscribers]]<186000000,"Macro","Mega"))) -> Micro | AQ24: =SUM((youtube_stats_raw[[#This Row],[lowest_yearly_earnings]] + youtube_stats_raw[[#This Row],[highest_yearly_earnings]])/2) -> 6482450 | AR24: =IF(youtube_stats_raw[[#This Row],[upload_frequency]]<=_xlfn.PERCENTILE.INC(AC:AC,0.2),"Very Low",IF(youtube_stats_raw[[#This Row],[upload_frequency]]<=_xlfn.PERCENTILE.INC(AC:AC,0.4),"Low",IF(youtube_stats_raw[[#This Row],[upload_frequency]]<=_xlfn.PERCENTILE.INC(AC:AC,0.6),"Medium",IF(youtube_stats_raw[[#This Row],[upload_frequency]]<=_xlfn.PERCENTILE.INC(AC:AC,0.8),"High","Very High")))) -> Very High
A25: 27 | B25: Colors TV | C25: 64600000 | D25: 61510906457 | E25: Shows | F25: Colors TV | G25: 112915 | H25: India | I25: IN | J25: Entertainment | K25: 10 | L25: 9 | M25: 9 | N25: 1188000000 | O25: 296900 | P25: 4800000 | Q25: 3600000 | R25: 57000000 | S25: 1100000 | T25: 2008 | U25: Jun | V25: 13 | W25: 28.1 | X25: 1366417754 | Y25: 5.36 | Z25: 471031528 | AA25: 20.593684 | AB25: 78.96288 | AC25: 588.09896 | AD25: 544754.08 | AE25: 572.11177 | AF25: 0.0010502203 | AG25: 78.034942 | AH25: 952.18121 | AI25: 18 | AJ25: 4503100 | AK25: 53400000 | AL25: 61111.111 | AM25: =youtube_stats_raw[[#This Row],[subscribers_for_last_30_days]] / youtube_stats_raw[[#This Row],[subscribers]] -> 0.017027864 | AN25: =IF(AND(youtube_stats_raw[[#This Row],[upload_frequency]]>23.1077381,youtube_stats_raw[[#This Row],[ engagement_rate]]<=0),"High",IF(OR(youtube_stats_raw[[#This Row],[upload_frequency]]>23.1077381,youtube_stats_raw[[#This Row],[ engagement_rate]]<=0),"Medium","Low")) -> Medium | AO25: =DATE(T25, MATCH(U25,{"Jan","Feb","Mar","Apr","May","Jun","Jul","Aug","Sep","Oct","Nov","Dec"},0), V25) -> 39612 | AP25: =IF(youtube_stats_raw[[#This Row],[subscribers]]<70000000,"Micro",IF(youtube_stats_raw[[#This Row],[subscribers]]<128000000,"Mid",IF(youtube_stats_raw[[#This Row],[subscribers]]<186000000,"Macro","Mega"))) -> Micro | AQ25: =SUM((youtube_stats_raw[[#This Row],[lowest_yearly_earnings]] + youtube_stats_raw[[#This Row],[highest_yearly_earnings]])/2) -> 30300000 | AR25: =IF(youtube_stats_raw[[#This Row],[upload_frequency]]<=_xlfn.PERCENTILE.INC(AC:AC,0.2),"Very Low",IF(youtube_stats_raw[[#This Row],[upload_frequency]]<=_xlfn.PERCENTILE.INC(AC:AC,0.4),"Low",IF(youtube_stats_raw[[#This Row],[upload_frequency]]<=_xlfn.PERCENTILE.INC(AC:AC,0.6),"Medium",IF(youtube_stats_raw[[#This Row],[upload_frequency]]<=_xlfn.PERCENTILE.INC(AC:AC,0.8),"High","Very High")))) -> Very High
A26: 28 | B26: T-Series Bhakti Sagar | C26: 61000000 | D26: 29533230328 | E26: Music | F26: T- SERIES BHAKTI SAGAR | G26: 13 | H26: India | I26: IN | J26: Music | K26: 4053938 | L26: 5803 | M26: 5744 | N26: 10 | O26: 0 | P26: 0 | Q26: 0 | R26: 0 | S26: 0 | T26: 2018 | U26: Aug | V26: 3 | W26: 28.1 | X26: 1366417754 | Y26: 5.36 | Z26: 471031528 | AA26: 20.593684 | AB26: 78.96288 | AC26: 0.18055556 | AD26: 2.2717869e+09 | AE26: 4692307.7 | AF26: 0.00206547 | AG26: 0 | AH26: 484.15132 | AI26: 8 | AJ26: 0 | AK26: 0 | AL26: 0 | AM26: =youtube_stats_raw[[#This Row],[subscribers_for_last_30_days]] / youtube_stats_raw[[#This Row],[subscribers]] -> 0 | AN26: =IF(AND(youtube_stats_raw[[#This Row],[upload_frequency]]>23.1077381,youtube_stats_raw[[#This Row],[ engagement_rate]]<=0),"High",IF(OR(youtube_stats_raw[[#This Row],[upload_frequency]]>23.1077381,youtube_stats_raw[[#This Row],[ engagement_rate]]<=0),"Medium","Low")) -> Medium | AO26: =DATE(T26, MATCH(U26,{"Jan","Feb","Mar","Apr","May","Jun","Jul","Aug","Sep","Oct","Nov","Dec"},0), V26) -> 43315 | AP26: =IF(youtube_stats_raw[[#This Row],[subscribers]]<70000000,"Micro",IF(youtube_stats_raw[[#This Row],[subscribers]]<128000000,"Mid",IF(youtube_stats_raw[[#This Row],[subscribers]]<186000000,"Macro","Mega"))) -> Micro | AQ26: =SUM((youtube_stats_raw[[#This Row],[lowest_yearly_earnings]] + youtube_stats_raw[[#This Row],[highest_yearly_earnings]])/2) -> 0 | AR26: =IF(youtube_stats_raw[[#This Row],[upload_frequency]]<=_xlfn.PERCENTILE.INC(AC:AC,0.2),"Very Low",IF(youtube_stats_raw[[#This Row],[upload_frequency]]<=_xlfn.PERCENTILE.INC(AC:AC,0.4),"Low",IF(youtube_stats_raw[[#This Row],[upload_frequency]]<=_xlfn.PERCENTILE.INC(AC:AC,0.6),"Medium",IF(youtube_stats_raw[[#This Row],[upload_frequency]]<=_xlfn.PERCENTILE.INC(AC:AC,0.8),"High","Very High")))) -> Very Low
A27: 29 | B27: Dude Perfect | C27: 59500000 | D27: 16241549158 | E27: Sports | F27: Dude Perfect | G27: 389 | H27: United States | I27: US | J27: Sports | K27: 182 | L27: 9 | M27: 3 | N27: 141200000 | O27: 35300 | P27: 564800 | Q27: 423600 | R27: 6800000 | S27: 100000 | T27: 2009 | U27: Mar | V27: 17 | W27: 88.2 | X27: 328239523 | Y27: 14.7 | Z27: 270663028 | AA27: 37.09024 | AB27: -95.712891 | AC27: 2.1611111 | AD27: 41752054 | AE27: 152956.3 | AF27: 0.0036634436 | AG27: 34.775008 | AH27: 272.96721 | AI27: 17 | AJ27: 529500 | AK27: 6376400 | AL27: 5882.3529 | AM27: =youtube_stats_raw[[#This Row],[subscribers_for_last_30_days]] / youtube_stats_raw[[#This Row],[subscribers]] -> 0.0016806723 | AN27: =IF(AND(youtube_stats_raw[[#This Row],[upload_frequency]]>23.1077381,youtube_stats_raw[[#This Row],[ engagement_rate]]<=0),"High",IF(OR(youtube_stats_raw[[#This Row],[upload_frequency]]>23.1077381,youtube_stats_raw[[#This Row],[ engagement_rate]]<=0),"Medium","Low")) -> Low | AO27: =DATE(T27, MATCH(U27,{"Jan","Feb","Mar","Apr","May","Jun","Jul","Aug","Sep","Oct","Nov","Dec"},0), V27) -> 39889 | AP27: =IF(youtube_stats_raw[[#This Row],[subscribers]]<70000000,"Micro",IF(youtube_stats_raw[[#This Row],[subscribers]]<128000000,"Mid",IF(youtube_stats_raw[[#This Row],[subscribers]]<186000000,"Macro","Mega"))) -> Micro | AQ27: =SUM((youtube_stats_raw[[#This Row],[lowest_yearly_earnings]] + youtube_stats_raw[[#This Row],[highest_yearly_earnings]])/2) -> 3611800 | AR27: =IF(youtube_stats_raw[[#This Row],[upload_frequency]]<=_xlfn.PERCENTILE.INC(AC:AC,0.2),"Very Low",IF(youtube_stats_raw[[#This Row],[upload_frequency]]<=_xlfn.PERCENTILE.INC(AC:AC,0.4),"Low",IF(youtube_stats_raw[[#This Row],[upload_frequency]]<=_xlfn.PERCENTILE.INC(AC:AC,0.6),"Medium",IF(youtube_stats_raw[[#This Row],[upload_frequency]]<=_xlfn.PERCENTILE.INC(AC:AC,0.8),"High","Very High")))) -> Low
A28: 30 | B28: Movieclips | C28: 59500000 | D28: 59316472754 | E28: Film & Animation | F28: Movieclips | G28: 39113 | H28: United States | I28: US | J28: Film | K28: 11 | L28: 9 | M28: 3 | N28: 114668000 | O28: 28700 | P28: 458700 | Q28: 344000 | R28: 5500000 | S28: 100000 | T28: 2006 | U28: Apr | V28: 28 | W28: 88.2 | X28: 328239523 | Y28: 14.7 | Z28: 270663028 | AA28: 37.09024 | AB28: -95.712891 | AC28: 181.0787 | AD28: 1516541.1 | AE28: 1521.2333 | AF28: 0.001003094 | AG28: 7.7330964 | AH28: 996.91551 | AI28: 20 | AJ28: 430000 | AK28: 5156000 | AL28: 5000 | AM28: =youtube_stats_raw[[#This Row],[subscribers_for_last_30_days]] / youtube_stats_raw[[#This Row],[subscribers]] -> 0.0016806723 | AN28: =IF(AND(youtube_stats_raw[[#This Row],[upload_frequency]]>23.1077381,youtube_stats_raw[[#This Row],[ engagement_rate]]<=0),"High",IF(OR(youtube_stats_raw[[#This Row],[upload_frequency]]>23.1077381,youtube_stats_raw[[#This Row],[ engagement_rate]]<=0),"Medium","Low")) -> Medium | AO28: =DATE(T28, MATCH(U28,{"Jan","Feb","Mar","Apr","May","Jun","Jul","Aug","Sep","Oct","Nov","Dec"},0), V28) -> 38835 | AP28: =IF(youtube_stats_raw[[#This Row],[subscribers]]<70000000,"Micro",IF(youtube_stats_raw[[#This Row],[subscribers]]<128000000,"Mid",IF(youtube_stats_raw[[#This Row],[subscribers]]<186000000,"Macro","Mega"))) -> Micro | AQ28: =SUM((youtube_stats_raw[[#This Row],[lowest_yearly_earnings]] + youtube_stats_raw[[#This Row],[highest_yearly_earnings]])/2) -> 2922000 | AR28: =IF(youtube_stats_raw[[#This Row],[upload_frequency]]<=_xlfn.PERCENTILE.INC(AC:AC,0.2),"Very Low",IF(youtube_stats_raw[[#This Row],[upload_frequency]]<=_xlfn.PERCENTILE.INC(AC:AC,0.4),"Low",IF(youtube_stats_raw[[#This Row],[upload_frequency]]<=_xlfn.PERCENTILE.INC(AC:AC,0.6),"Medium",IF(youtube_stats_raw[[#This Row],[upload_frequency]]<=_xlfn.PERCENTILE.INC(AC:AC,0.8),"High","Very High")))) -> Very High
A29: 31 | B29: Tips Official | C29: 59300000 | D29: 33431802698 | E29: Music | F29: Tips Official | G29: 4741 | H29: India | I29: IN | J29: Music | K29: 30 | L29: 11 | M29: 10 | N29: 422634000 | O29: 105700 | P29: 1700000 | Q29: 1300000 | R29: 20300000 | S29: 600000 | T29: 2007 | U29: May | V29: 22 | W29: 28.1 | X29: 1366417754 | Y29: 5.36 | Z29: 471031528 | AA29: 20.593684 | AB29: 78.96288 | AC29: 23.240196 | AD29: 7051635.2 | AE29: 12507.91 | AF29: 0.0017737602 | AG29: 50.849786 | AH29: 563.77408 | AI29: 19 | AJ29: 1594300 | AK29: 19000000 | AL29: 31578.947 | AM29: =youtube_stats_raw[[#This Row],[subscribers_for_last_30_days]] / youtube_stats_raw[[#This Row],[subscribers]] -> 0.010118044 | AN29: =IF(AND(youtube_stats_raw[[#This Row],[upload_frequency]]>23.1077381,youtube_stats_raw[[#This Row],[ engagement_rate]]<=0),"High",IF(OR(youtube_stats_raw[[#This Row],[upload_frequency]]>23.1077381,youtube_stats_raw[[#This Row],[ engagement_rate]]<=0),"Medium","Low")) -> Medium | AO29: =DATE(T29, MATCH(U29,{"Jan","Feb","Mar","Apr","May","Jun","Jul","Aug","Sep","Oct","Nov","Dec"},0), V29) -> 39224 | AP29: =IF(youtube_stats_raw[[#This Row],[subscribers]]<70000000,"Micro",IF(youtube_stats_raw[[#This Row],[subscribers]]<128000000,"Mid",IF(youtube_stats_raw[[#This Row],[subscribers]]<186000000,"Macro","Mega"))) -> Micro | AQ29: =SUM((youtube_stats_raw[[#This Row],[lowest_yearly_earnings]] + youtube_stats_raw[[#This Row],[highest_yearly_earnings]])/2) -> 10800000 | AR29: =IF(youtube_stats_raw[[#This Row],[upload_frequency]]<=_xlfn.PERCENTILE.INC(AC:AC,0.2),"Very Low",IF(youtube_stats_raw[[#This Row],[upload_frequency]]<=_xlfn.PERCENTILE.INC(AC:AC,0.4),"Low",IF(youtube_stats_raw[[#This Row],[upload_frequency]]<=_xlfn.PERCENTILE.INC(AC:AC,0.6),"Medium",IF(youtube_stats_raw[[#This Row],[upload_frequency]]<=_xlfn.PERCENTILE.INC(AC:AC,0.8),"High","Very High")))) -> High
... A66: 73 | B66: Little Baby Bum - Nursery Rhymes & Kids Songs | C66: 40900000 | D66: 39450824833 | E66: Education | F66: Little Baby Bum - Nursery Rhymes & Kids Songs | G66: 2423 | H66: United States | I66: US | J66: Education | K66: 22 | L66: 22 | M66: 7 | N66: 98775000 | O66: 24700 | P66: 395100 | Q66: 296300 | R66: 4700000 | S66: 100000 | T66: 2011 | U66: Jun | V66: 22 | W66: 88.2 | X66: 328239523 | Y66: 14.7 | Z66: 270663028 | AA66: 37.09024 | AB66: -95.712891 | AC66: 15.532051 | AD66: 16281810 | AE66: 16879.901 | AF66: 0.0010367337 | AG66: 10.015 | AH66: 964.56784 | AI66: 15 | AJ66: 370400 | AK66: 4403700 | AL66: 6666.6667 | AM66: =youtube_stats_raw[[#This Row],[subscribers_for_last_30_days]] / youtube_stats_raw[[#This Row],[subscribers]] -> 0.0024449878 | AN66: =IF(AND(youtube_stats_raw[[#This Row],[upload_frequency]]>23.1077381,youtube_stats_raw[[#This Row],[ engagement_rate]]<=0),"High",IF(OR(youtube_stats_raw[[#This Row],[upload_frequency]]>23.1077381,youtube_stats_raw[[#This Row],[ engagement_rate]]<=0),"Medium","Low")) -> Low | AO66: =DATE(T66, MATCH(U66,{"Jan","Feb","Mar","Apr","May","Jun","Jul","Aug","Sep","Oct","Nov","Dec"},0), V66) -> 40716 | AP66: =IF(youtube_stats_raw[[#This Row],[subscribers]]<70000000,"Micro",IF(youtube_stats_raw[[#This Row],[subscribers]]<128000000,"Mid",IF(youtube_stats_raw[[#This Row],[subscribers]]<186000000,"Macro","Mega"))) -> Micro | AQ66: =SUM((youtube_stats_raw[[#This Row],[lowest_yearly_earnings]] + youtube_stats_raw[[#This Row],[highest_yearly_earnings]])/2) -> 2498150 | AR66: =IF(youtube_stats_raw[[#This Row],[upload_frequency]]<=_xlfn.PERCENTILE.INC(AC:AC,0.2),"Very Low",IF(youtube_stats_raw[[#This Row],[upload_frequency]]<=_xlfn.PERCENTILE.INC(AC:AC,0.4),"Low",IF(youtube_stats_raw[[#This Row],[upload_frequency]]<=_xlfn.PERCENTILE.INC(AC:AC,0.6),"Medium",IF(youtube_stats_raw[[#This Row],[upload_frequency]]<=_xlfn.PERCENTILE.INC(AC:AC,0.8),"High","Very High")))) -> High
A67: 74 | B67: Luisito Comunica | C67: 40600000 | D67: 8670473639 | E67: Comedy | F67: Luis Arturo Villar Sudek | G67: 0 | H67: Mexico | I67: MX | J67: Comedy | K67: 3612215 | L67: 3021 | O67: 0 | P67: 0 | Q67: 0 | R67: 0 | S67: 0 | T67: 2010 | U67: Jun | V67: 18 | W67: 40.2 | X67: 126014024 | Y67: 3.42 | Z67: 102626859 | AA67: 23.634501 | AB67: -102.55278 | AC67: 0 | AD67: #NUM! | AE67: #NUM! | AF67: 0.0046825585 | AG67: 0 | AH67: 213.55846 | AI67: 16 | AJ67: 0 | AK67: 0 | AL67: 0 | AM67: =youtube_stats_raw[[#This Row],[subscribers_for_last_30_days]] / youtube_stats_raw[[#This Row],[subscribers]] -> 0 | AN67: =IF(AND(youtube_stats_raw[[#This Row],[upload_frequency]]>23.1077381,youtube_stats_raw[[#This Row],[ engagement_rate]]<=0),"High",IF(OR(youtube_stats_raw[[#This Row],[upload_frequency]]>23.1077381,youtube_stats_raw[[#This Row],[ engagement_rate]]<=0),"Medium","Low")) -> Medium | AO67: =DATE(T67, MATCH(U67,{"Jan","Feb","Mar","Apr","May","Jun","Jul","Aug","Sep","Oct","Nov","Dec"},0), V67) -> 40347 | AP67: =IF(youtube_stats_raw[[#This Row],[subscribers]]<70000000,"Micro",IF(youtube_stats_raw[[#This Row],[subscribers]]<128000000,"Mid",IF(youtube_stats_raw[[#This Row],[subscribers]]<186000000,"Macro","Mega"))) -> Micro | AQ67: =SUM((youtube_stats_raw[[#This Row],[lowest_yearly_earnings]] + youtube_stats_raw[[#This Row],[highest_yearly_earnings]])/2) -> 0 | AR67: =IF(youtube_stats_raw[[#This Row],[upload_frequency]]<=_xlfn.PERCENTILE.INC(AC:AC,0.2),"Very Low",IF(youtube_stats_raw[[#This Row],[upload_frequency]]<=_xlfn.PERCENTILE.INC(AC:AC,0.4),"Low",IF(youtube_stats_raw[[#This Row],[upload_frequency]]<=_xlfn.PERCENTILE.INC(AC:AC,0.6),"Medium",IF(youtube_stats_raw[[#This Row],[upload_frequency]]<=_xlfn.PERCENTILE.INC(AC:AC,0.8),"High","Very High")))) -> Very Low
A68: 77 | B68: shfa2 - ï¿½ï¿½ | C68: 39700000 | D68: 23884824160 | E68: People & Blogs | F68: shfa2 - ï¿½ï¿½ | G68: 1596 | H68: United Arab Emirates | I68: AE | J68: People | K68: 81 | L68: 1 | M68: 2 | N68: 247731000 | O68: 61900 | P68: 990900 | Q68: 743200 | R68: 11900000 | S68: 300000 | T68: 2017 | U68: Nov | V68: 6 | W68: 36.8 | X68: 9770529 | Y68: 2.35 | Z68: 8479744 | AA68: 23.424076 | AB68: 53.847818 | AC68: 19 | AD68: 14965429 | AE68: 24874.687 | AF68: 0.0016621433 | AG68: 41.486594 | AH68: 601.63285 | AI68: 9 | AJ68: 929000 | AK68: 11156800 | AL68: 33333.333 | AM68: =youtube_stats_raw[[#This Row],[subscribers_for_last_30_days]] / youtube_stats_raw[[#This Row],[subscribers]] -> 0.0075566751 | AN68: =IF(AND(youtube_stats_raw[[#This Row],[upload_frequency]]>23.1077381,youtube_stats_raw[[#This Row],[ engagement_rate]]<=0),"High",IF(OR(youtube_stats_raw[[#This Row],[upload_frequency]]>23.1077381,youtube_stats_raw[[#This Row],[ engagement_rate]]<=0),"Medium","Low")) -> Low | AO68: =DATE(T68, MATCH(U68,{"Jan","Feb","Mar","Apr","May","Jun","Jul","Aug","Sep","Oct","Nov","Dec"},0), V68) -> 43045 | AP68: =IF(youtube_stats_raw[[#This Row],[subscribers]]<70000000,"Micro",IF(youtube_stats_raw[[#This Row],[subscribers]]<128000000,"Mid",IF(youtube_stats_raw[[#This Row],[subscribers]]<186000000,"Macro","Mega"))) -> Micro | AQ68: =SUM((youtube_stats_raw[[#This Row],[lowest_yearly_earnings]] + youtube_stats_raw[[#This Row],[highest_yearly_earnings]])/2) -> 6321600 | AR68: =IF(youtube_stats_raw[[#This Row],[upload_frequency]]<=_xlfn.PERCENTILE.INC(AC:AC,0.2),"Very Low",IF(youtube_stats_raw[[#This Row],[upload_frequency]]<=_xlfn.PERCENTILE.INC(AC:AC,0.4),"Low",IF(youtube_stats_raw[[#This Row],[upload_frequency]]<=_xlfn.PERCENTILE.INC(AC:AC,0.6),"Medium",IF(youtube_stats_raw[[#This Row],[upload_frequency]]<=_xlfn.PERCENTILE.INC(AC:AC,0.8),"High","Very High")))) -> High
